Workbook

Sheet 0_Control
A1: PRIME ORIGINS — CALIFORNIA HASH + MOROCCAN IMPORT MODEL
A2: v1.0 · June 2026 · USD · 36-month engine · Logic adapted from Seed-to-Shelf May 28 USD model v0.7
A4: Setting | B4: Value | C4: Notes
A5: Scenario (1 = Case A California only · 2 = Case B + Moroccan imports) | B5: 2 | C5: Blue input — switch cases
A6: Model start month | B6: M1 = Jan 2027 | C6: Round close assumed M1
A7: Model months | B7: 36
A8: Reporting currency | B8: USD
A9: Equity raise (SAFE) | B9: 5000000 | C9: Per investor deck

Sheet 1_Assumptions
A1: ASSUMPTIONS REGISTRY
A2: Blue = hardcoded input. Black = derived formula. Sources: Vista Ranch Phase 1 cultivation model (per investor deck, Jun 2026); estimates flagged for diligence.
A4: ID | B4: Family | C4: Assumption | D4: Value | E4: Unit | F4: Source / Notes
A5: BUD_LBS_S1 | B5: Production | C5: Season 1 bud harvest | D5: 2094 | E5: lbs | F5: Per investor deck — Vista Ranch Phase 1 (60,000 sq ft)
A6: TRIM_LBS_S1 | B6: Production | C6: Season 1 trim (+40% of bud) | D6: =D5*0.4 -> 837.6 | E6: lbs | F6: Derived — 40% of bud
A7: SPLIT_LARGE | B7: Production | C7: Grade split — larges | D7: 0.3 | E7: % of bud | F7: Per deck
A8: SPLIT_MED | B8: Production | C8: Grade split — mediums | D8: 0.4 | E8: % of bud | F8: Per deck
A9: SPLIT_SMALL | B9: Production | C9: Grade split — smalls | D9: 0.3 | E9: % of bud | F9: Per deck
A10: S2_SCALE | B10: Production | C10: Season 2 scale factor | D10: 1.25 | E10: x | F10: Canopy efficiency + genetics — estimate
A11: S3_SCALE | B11: Production | C11: Season 3 scale factor | D11: 1.5 | E11: x | F11: Estimate
A12: G_PER_LB | B12: Production | C12: Grams per pound | D12: 453.592 | E12: g/lb | F12: Constant
A13: JARS_PER_LB | B13: Conversion | C13: Quarter-oz jars per lb (larges) | D13: 64 | E13: units/lb | F13: Vista Ranch model (incl. handling loss)
A14: ROSIN_G_PER_LB | B14: Conversion | C14: Rosin g per lb (mediums) | D14: 68 | E14: g/lb | F14: ~15% solventless yield — Vista Ranch model
A15: PREROLL_POOL_PCT | B15: Conversion | C15: Smalls+trim pool to pre-roll flower | D15: 0.3 | E15: % | F15: Vista Ranch model
A16: HASH_POOL_PCT | B16: Conversion | C16: Smalls+trim pool to hash input | D16: 0.7 | E16: % | F16: Vista Ranch model
A17: PREROLL_G | B17: Conversion | C17: Flower per pre-roll | D17: 0.5 | E17: g/unit | F17: Vista Ranch model
A18: HASH_YIELD_PCT | B18: Conversion | C18: Hash yield on input flower | D18: 0.143 | E18: % | F18: Ice-water hash return — Vista Ranch model
... A26: B2C_FULFIL_PCT | B26: Channel | C26: B2C fulfilment & retail cost % of B2C revenue | D26: 0.1 | E26: % | F26: Payments, fulfilment, retail compliance — estimate
A27: BLEND_FACTOR | B27: Channel | C27: Blended price as % of retail (for implied-price maths) | D27: =D23+(1-D23)*D24 -> 0.75 | E27: % | F27: Derived — 50/50 mix
A28: SELL_PCT_BLEND | B28: Channel | C28: Blended selling cost % of realised revenue | D28: =(D23*D26+(1-D23)*D24*D25)/D27 -> 0.11666667 | E28: % | F28: Revenue-weighted across channels
A29: RETAIL_JAR | B29: Channel | C29: Implied B2C retail price — jar | D29: =D19/D27 -> 74.666667 | E29: USD/unit | F29: Deck blended ÷ blend factor
A30: RETAIL_ROSIN | B30: Channel | C30: Implied B2C retail price — rosin | D30: =D20/D27 -> 58.666667 | E30: USD/g
A31: RETAIL_HASH | B31: Channel | C31: Implied B2C retail price — hash | D31: =D21/D27 -> 46.666667 | E31: USD/g
A32: RETAIL_PREROLL | B32: Channel | C32: Implied B2C retail price — pre-roll | D32: =D22/D27 -> 17.333333 | E32: USD/unit
A33: WS_JAR | B33: Channel | C33: Implied B2B wholesale price — jar | D33: =D29*D24 -> 37.333333 | E33: USD/unit | F33: Retail × wholesale %
A34: AGRI_MONTH | B34: Pricing | C34: Agritourism & seeds per month | D34: 24167 | E34: USD/mo | F34: $0.29M over Phase 1 — per deck
A35: AGRI_START_M | B35: Timing | C35: Agritourism start month | D35: 7 | E35: month # | F35: Post-build
A36: SALES_START_S1 | B36: Timing | C36: Season 1 sales start month | D36: 11 | E36: month # | F36: Harvest M10 → first sales M11
A37: SALES_MONTHS | B37: Timing | C37: Sales window per season | D37: 8 | E37: months | F37: Sell-through period
A38: SALES_START_S2 | B38: Timing | C38: Season 2 sales start month | D38: 23 | E38: month #
A39: SALES_START_S3 | B39: Timing | C39: Season 3 sales start month | D39: 35 | E39: month # | F39: Partial within 36-month engine
A40: CULT_START_S1 | B40: Timing | C40: Season 1 cultivation cost start | D40: 3 | E40: month #
A41: CULT_MONTHS | B41: Timing | C41: Cultivation cost window | D41: 8 | E41: months | F41: Plant → harvest
A42: IMP_START_M | B42: Import | C42: Moroccan import sales start month | D42: 13 | E42: month # | F42: Subject to regulatory pathway — diligence item
A43: IMP_KG_Y1 | B43: Import | C43: Import volume M13–M18 | D43: 30 | E43: kg/mo | F43: Estimate — partner capacity
A44: IMP_KG_Y2 | B44: Import | C44: Import volume M19–M30 | D44: 60 | E44: kg/mo | F44: Estimate
A45: IMP_KG_Y3 | B45: Import | C45: Import volume M31–M36 | D45: 100 | E45: kg/mo | F45: Estimate
A46: IMP_PRICE_G | B46: Import | C46: Moroccan hash price (blended realised) | D46: 10.5 | E46: USD/g | F46: Best guess — $14/g retail, $7/g wholesale, 50/50 mix
A47: IMP_COST_G | B47: Import | C47: Landed cost (product+freight+duty+compliance) | D47: 4.5 | E47: USD/g | F47: Estimate — confirm with partners
A48: IMP_COMPLIANCE_MONTH | B48: Import | C48: Import compliance & docs per month | D48: 10000 | E48: USD/mo | F48: Estimate
...

Sheet 2_Monthly_Model
A1: MONTHLY MODEL — M1–M36
A2: Case toggle on 0_Control. All formulas; assumptions on 1_Assumptions.
B4: Month | C4: 1 | D4: 2 | E4: 3 | F4: 4 | G4: 5 | H4: 6 | I4: 7 | J4: 8 | K4: 9 | L4: 10 | M4: 11 | N4: 12 | O4: 13 | P4: 14 | Q4: 15 | R4: 16 | S4: 17 | T4: 18 | U4: 19 | V4: 20 | W4: 21 | X4: 22 | Y4: 23 | Z4: 24 | AA4: 25 | AB4: 26 | AC4: 27 | AD4: 28 | AE4: 29 | AF4: 30 | AG4: 31 | AH4: 32 | AI4: 33 | AJ4: 34 | AK4: 35 | AL4: 36
B6: SALES & PRODUCTION
B7: S1 sale fraction | C7: =IF(AND(C$4>='1_Assumptions'!$D$36,C$4<'1_Assumptions'!$D$36+'1_Assumptions'!$D$37),1/'1_Assumptions'!$D$37,0) -> 0 | D7: =IF(AND(D$4>='1_Assumptions'!$D$36,D$4<'1_Assumptions'!$D$36+'1_Assumptions'!$D$37),1/'1_Assumptions'!$D$37,0) -> 0 | E7: =IF(AND(E$4>='1_Assumptions'!$D$36,E$4<'1_Assumptions'!$D$36+'1_Assumptions'!$D$37),1/'1_Assumptions'!$D$37,0) -> 0 | F7: =IF(AND(F$4>='1_Assumptions'!$D$36,F$4<'1_Assumptions'!$D$36+'1_Assumptions'!$D$37),1/'1_Assumptions'!$D$37,0) -> 0 | G7: =IF(AND(G$4>='1_Assumptions'!$D$36,G$4<'1_Assumptions'!$D$36+'1_Assumptions'!$D$37),1/'1_Assumptions'!$D$37,0) -> 0 | H7: =IF(AND(H$4>='1_Assumptions'!$D$36,H$4<'1_Assumptions'!$D$36+'1_Assumptions'!$D$37),1/'1_Assumptions'!$D$37,0) -> 0 | I7: =IF(AND(I$4>='1_Assumptions'!$D$36,I$4<'1_Assumptions'!$D$36+'1_Assumptions'!$D$37),1/'1_Assumptions'!$D$37,0) -> 0 | J7: =IF(AND(J$4>='1_Assumptions'!$D$36,J$4<'1_Assumptions'!$D$36+'1_Assumptions'!$D$37),1/'1_Assumptions'!$D$37,0) -> 0 | ... AL7: =IF(AND(AL$4>='1_Assumptions'!$D$36,AL$4<'1_Assumptions'!$D$36+'1_Assumptions'!$D$37),1/'1_Assumptions'!$D$37,0) -> 0
B8: S2 sale fraction | C8: =IF(AND(C$4>='1_Assumptions'!$D$38,C$4<'1_Assumptions'!$D$38+'1_Assumptions'!$D$37),1/'1_Assumptions'!$D$37,0) -> 0 | D8: =IF(AND(D$4>='1_Assumptions'!$D$38,D$4<'1_Assumptions'!$D$38+'1_Assumptions'!$D$37),1/'1_Assumptions'!$D$37,0) -> 0 | E8: =IF(AND(E$4>='1_Assumptions'!$D$38,E$4<'1_Assumptions'!$D$38+'1_Assumptions'!$D$37),1/'1_Assumptions'!$D$37,0) -> 0 | F8: =IF(AND(F$4>='1_Assumptions'!$D$38,F$4<'1_Assumptions'!$D$38+'1_Assumptions'!$D$37),1/'1_Assumptions'!$D$37,0) -> 0 | G8: =IF(AND(G$4>='1_Assumptions'!$D$38,G$4<'1_Assumptions'!$D$38+'1_Assumptions'!$D$37),1/'1_Assumptions'!$D$37,0) -> 0 | H8: =IF(AND(H$4>='1_Assumptions'!$D$38,H$4<'1_Assumptions'!$D$38+'1_Assumptions'!$D$37),1/'1_Assumptions'!$D$37,0) -> 0 | I8: =IF(AND(I$4>='1_Assumptions'!$D$38,I$4<'1_Assumptions'!$D$38+'1_Assumptions'!$D$37),1/'1_Assumptions'!$D$37,0) -> 0 | J8: =IF(AND(J$4>='1_Assumptions'!$D$38,J$4<'1_Assumptions'!$D$38+'1_Assumptions'!$D$37),1/'1_Assumptions'!$D$37,0) -> 0 | ... AL8: =IF(AND(AL$4>='1_Assumptions'!$D$38,AL$4<'1_Assumptions'!$D$38+'1_Assumptions'!$D$37),1/'1_Assumptions'!$D$37,0) -> 0
B9: S3 sale fraction | C9: =IF(AND(C$4>='1_Assumptions'!$D$39,C$4<'1_Assumptions'!$D$39+'1_Assumptions'!$D$37),1/'1_Assumptions'!$D$37,0) -> 0 | D9: =IF(AND(D$4>='1_Assumptions'!$D$39,D$4<'1_Assumptions'!$D$39+'1_Assumptions'!$D$37),1/'1_Assumptions'!$D$37,0) -> 0 | E9: =IF(AND(E$4>='1_Assumptions'!$D$39,E$4<'1_Assumptions'!$D$39+'1_Assumptions'!$D$37),1/'1_Assumptions'!$D$37,0) -> 0 | F9: =IF(AND(F$4>='1_Assumptions'!$D$39,F$4<'1_Assumptions'!$D$39+'1_Assumptions'!$D$37),1/'1_Assumptions'!$D$37,0) -> 0 | G9: =IF(AND(G$4>='1_Assumptions'!$D$39,G$4<'1_Assumptions'!$D$39+'1_Assumptions'!$D$37),1/'1_Assumptions'!$D$37,0) -> 0 | H9: =IF(AND(H$4>='1_Assumptions'!$D$39,H$4<'1_Assumptions'!$D$39+'1_Assumptions'!$D$37),1/'1_Assumptions'!$D$37,0) -> 0 | I9: =IF(AND(I$4>='1_Assumptions'!$D$39,I$4<'1_Assumptions'!$D$39+'1_Assumptions'!$D$37),1/'1_Assumptions'!$D$37,0) -> 0 | J9: =IF(AND(J$4>='1_Assumptions'!$D$39,J$4<'1_Assumptions'!$D$39+'1_Assumptions'!$D$37),1/'1_Assumptions'!$D$37,0) -> 0 | ... AL9: =IF(AND(AL$4>='1_Assumptions'!$D$39,AL$4<'1_Assumptions'!$D$39+'1_Assumptions'!$D$37),1/'1_Assumptions'!$D$37,0) -> 0.125
B10: Season-scaled sales factor | C10: =C7*1+C8*'1_Assumptions'!$D$10+C9*'1_Assumptions'!$D$11 -> 0 | D10: =D7*1+D8*'1_Assumptions'!$D$10+D9*'1_Assumptions'!$D$11 -> 0 | E10: =E7*1+E8*'1_Assumptions'!$D$10+E9*'1_Assumptions'!$D$11 -> 0 | F10: =F7*1+F8*'1_Assumptions'!$D$10+F9*'1_Assumptions'!$D$11 -> 0 | G10: =G7*1+G8*'1_Assumptions'!$D$10+G9*'1_Assumptions'!$D$11 -> 0 | H10: =H7*1+H8*'1_Assumptions'!$D$10+H9*'1_Assumptions'!$D$11 -> 0 | I10: =I7*1+I8*'1_Assumptions'!$D$10+I9*'1_Assumptions'!$D$11 -> 0 | J10: =J7*1+J8*'1_Assumptions'!$D$10+J9*'1_Assumptions'!$D$11 -> 0 | ... AL10: =AL7*1+AL8*'1_Assumptions'!$D$10+AL9*'1_Assumptions'!$D$11 -> 0.1875
B12: CALIFORNIA REVENUE
B13: Flower jars (units) | C13: =C10*'1_Assumptions'!$D$73 -> 0 | D13: =D10*'1_Assumptions'!$D$73 -> 0 | E13: =E10*'1_Assumptions'!$D$73 -> 0 | F13: =F10*'1_Assumptions'!$D$73 -> 0 | G13: =G10*'1_Assumptions'!$D$73 -> 0 | H13: =H10*'1_Assumptions'!$D$73 -> 0 | I13: =I10*'1_Assumptions'!$D$73 -> 0 | J13: =J10*'1_Assumptions'!$D$73 -> 0 | ... AL13: =AL10*'1_Assumptions'!$D$73 -> 7538.4
B14: Rosin (g) | C14: =C10*'1_Assumptions'!$D$74 -> 0 | D14: =D10*'1_Assumptions'!$D$74 -> 0 | E14: =E10*'1_Assumptions'!$D$74 -> 0 | F14: =F10*'1_Assumptions'!$D$74 -> 0 | G14: =G10*'1_Assumptions'!$D$74 -> 0 | H14: =H10*'1_Assumptions'!$D$74 -> 0 | I14: =I10*'1_Assumptions'!$D$74 -> 0 | J14: =J10*'1_Assumptions'!$D$74 -> 0 | ... AL14: =AL10*'1_Assumptions'!$D$74 -> 10679.4
B15: Hash (g) | C15: =C10*'1_Assumptions'!$D$76 -> 0 | D15: =D10*'1_Assumptions'!$D$76 -> 0 | E15: =E10*'1_Assumptions'!$D$76 -> 0 | F15: =F10*'1_Assumptions'!$D$76 -> 0 | G15: =G10*'1_Assumptions'!$D$76 -> 0 | H15: =H10*'1_Assumptions'!$D$76 -> 0 | I15: =I10*'1_Assumptions'!$D$76 -> 0 | J15: =J10*'1_Assumptions'!$D$76 -> 0 | ... AL15: =AL10*'1_Assumptions'!$D$76 -> 12478.876
B16: Pre-rolls (units) | C16: =C10*'1_Assumptions'!$D$75 -> 0 | D16: =D10*'1_Assumptions'!$D$75 -> 0 | E16: =E10*'1_Assumptions'!$D$75 -> 0 | F16: =F10*'1_Assumptions'!$D$75 -> 0 | G16: =G10*'1_Assumptions'!$D$75 -> 0 | H16: =H10*'1_Assumptions'!$D$75 -> 0 | I16: =I10*'1_Assumptions'!$D$75 -> 0 | J16: =J10*'1_Assumptions'!$D$75 -> 0 | ... AL16: =AL10*'1_Assumptions'!$D$75 -> 74798.455
B17: Product revenue | C17: =C13*'1_Assumptions'!$D$19+C14*'1_Assumptions'!$D$20+C15*'1_Assumptions'!$D$21+C16*'1_Assumptions'!$D$22 -> 0 | D17: =D13*'1_Assumptions'!$D$19+D14*'1_Assumptions'!$D$20+D15*'1_Assumptions'!$D$21+D16*'1_Assumptions'!$D$22 -> 0 | E17: =E13*'1_Assumptions'!$D$19+E14*'1_Assumptions'!$D$20+E15*'1_Assumptions'!$D$21+E16*'1_Assumptions'!$D$22 -> 0 | F17: =F13*'1_Assumptions'!$D$19+F14*'1_Assumptions'!$D$20+F15*'1_Assumptions'!$D$21+F16*'1_Assumptions'!$D$22 -> 0 | G17: =G13*'1_Assumptions'!$D$19+G14*'1_Assumptions'!$D$20+G15*'1_Assumptions'!$D$21+G16*'1_Assumptions'!$D$22 -> 0 | H17: =H13*'1_Assumptions'!$D$19+H14*'1_Assumptions'!$D$20+H15*'1_Assumptions'!$D$21+H16*'1_Assumptions'!$D$22 -> 0 | I17: =I13*'1_Assumptions'!$D$19+I14*'1_Assumptions'!$D$20+I15*'1_Assumptions'!$D$21+I16*'1_Assumptions'!$D$22 -> 0 | J17: =J13*'1_Assumptions'!$D$19+J14*'1_Assumptions'!$D$20+J15*'1_Assumptions'!$D$21+J16*'1_Assumptions'!$D$22 -> 0 | ... AL17: =AL13*'1_Assumptions'!$D$19+AL14*'1_Assumptions'!$D$20+AL15*'1_Assumptions'!$D$21+AL16*'1_Assumptions'!$D$22 -> 2301184.6
B18: Agritourism & seeds | C18: =IF(C$4>='1_Assumptions'!$D$35,'1_Assumptions'!$D$34,0) -> 0 | D18: =IF(D$4>='1_Assumptions'!$D$35,'1_Assumptions'!$D$34,0) -> 0 | E18: =IF(E$4>='1_Assumptions'!$D$35,'1_Assumptions'!$D$34,0) -> 0 | F18: =IF(F$4>='1_Assumptions'!$D$35,'1_Assumptions'!$D$34,0) -> 0 | G18: =IF(G$4>='1_Assumptions'!$D$35,'1_Assumptions'!$D$34,0) -> 0 | H18: =IF(H$4>='1_Assumptions'!$D$35,'1_Assumptions'!$D$34,0) -> 0 | I18: =IF(I$4>='1_Assumptions'!$D$35,'1_Assumptions'!$D$34,0) -> 24167 | J18: =IF(J$4>='1_Assumptions'!$D$35,'1_Assumptions'!$D$34,0) -> 24167 | ... AL18: =IF(AL$4>='1_Assumptions'!$D$35,'1_Assumptions'!$D$34,0) -> 24167
B19: California revenue | C19: =C17+C18 -> 0 | D19: =D17+D18 -> 0 | E19: =E17+E18 -> 0 | F19: =F17+F18 -> 0 | G19: =G17+G18 -> 0 | H19: =H17+H18 -> 0 | I19: =I17+I18 -> 24167 | J19: =J17+J18 -> 24167 | ... AL19: =AL17+AL18 -> 2325351.6
B21: MOROCCAN IMPORT (CASE B)
B22: Import volume (kg) | C22: =IF('0_Control'!$B$5=2,IF(C$4>='1_Assumptions'!$D$42,IF(C$4<=18,'1_Assumptions'!$D$43,IF(C$4<=30,'1_Assumptions'!$D$44,'1_Assumptions'!$D$45)),0),0) -> 0 | D22: =IF('0_Control'!$B$5=2,IF(D$4>='1_Assumptions'!$D$42,IF(D$4<=18,'1_Assumptions'!$D$43,IF(D$4<=30,'1_Assumptions'!$D$44,'1_Assumptions'!$D$45)),0),0) -> 0 | E22: =IF('0_Control'!$B$5=2,IF(E$4>='1_Assumptions'!$D$42,IF(E$4<=18,'1_Assumptions'!$D$43,IF(E$4<=30,'1_Assumptions'!$D$44,'1_Assumptions'!$D$45)),0),0) -> 0 | F22: =IF('0_Control'!$B$5=2,IF(F$4>='1_Assumptions'!$D$42,IF(F$4<=18,'1_Assumptions'!$D$43,IF(F$4<=30,'1_Assumptions'!$D$44,'1_Assumptions'!$D$45)),0),0) -> 0 | G22: =IF('0_Control'!$B$5=2,IF(G$4>='1_Assumptions'!$D$42,IF(G$4<=18,'1_Assumptions'!$D$43,IF(G$4<=30,'1_Assumptions'!$D$44,'1_Assumptions'!$D$45)),0),0) -> 0 | H22: =IF('0_Control'!$B$5=2,IF(H$4>='1_Assumptions'!$D$42,IF(H$4<=18,'1_Assumptions'!$D$43,IF(H$4<=30,'1_Assumptions'!$D$44,'1_Assumptions'!$D$45)),0),0) -> 0 | I22: =IF('0_Control'!$B$5=2,IF(I$4>='1_Assumptions'!$D$42,IF(I$4<=18,'1_Assumptions'!$D$43,IF(I$4<=30,'1_Assumptions'!$D$44,'1_Assumptions'!$D$45)),0),0) -> 0 | J22: =IF('0_Control'!$B$5=2,IF(J$4>='1_Assumptions'!$D$42,IF(J$4<=18,'1_Assumptions'!$D$43,IF(J$4<=30,'1_Assumptions'!$D$44,'1_Assumptions'!$D$45)),0),0) -> 0 | ... AL22: =IF('0_Control'!$B$5=2,IF(AL$4>='1_Assumptions'!$D$42,IF(AL$4<=18,'1_Assumptions'!$D$43,IF(AL$4<=30,'1_Assumptions'!$D$44,'1_Assumptions'!$D$45)),0),0) -> 100
B23: Import revenue | C23: =C22*1000*'1_Assumptions'!$D$46 -> 0 | D23: =D22*1000*'1_Assumptions'!$D$46 -> 0 | E23: =E22*1000*'1_Assumptions'!$D$46 -> 0 | F23: =F22*1000*'1_Assumptions'!$D$46 -> 0 | G23: =G22*1000*'1_Assumptions'!$D$46 -> 0 | H23: =H22*1000*'1_Assumptions'!$D$46 -> 0 | I23: =I22*1000*'1_Assumptions'!$D$46 -> 0 | J23: =J22*1000*'1_Assumptions'!$D$46 -> 0 | ... AL23: =AL22*1000*'1_Assumptions'!$D$46 -> 1050000
B25: TOTAL REVENUE | C25: =C19+C23 -> 0 | D25: =D19+D23 -> 0 | E25: =E19+E23 -> 0 | F25: =F19+F23 -> 0 | G25: =G19+G23 -> 0 | H25: =H19+H23 -> 0 | I25: =I19+I23 -> 24167 | J25: =J19+J23 -> 24167 | ... AL25: =AL19+AL23 -> 3375351.6
B27: COST OF GOODS
B28: Cultivation direct cost | C28: =(IF(AND(C$4>='1_Assumptions'!$D$40,C$4<'1_Assumptions'!$D$40+'1_Assumptions'!$D$41),1,0)*1+IF(AND(C$4>='1_Assumptions'!$D$40+12,C$4<'1_Assumptions'!$D$40+12+'1_Assumptions'!$D$41),1,0)*'1_Assumptions'!$D$10+IF(AND(C$4>='1_Assumptions'!$D$40+24,C$4<'1_Assumptions'!$D$40+24+'1_Assumptions'!$D$41),1,0)*'1_Assumptions'!$D$11)*'1_Assumptions'!$D$49/'1_Assumptions'!$D$41 -> 0 | D28: =(IF(AND(D$4>='1_Assumptions'!$D$40,D$4<'1_Assumptions'!$D$40+'1_Assumptions'!$D$41),1,0)*1+IF(AND(D$4>='1_Assumptions'!$D$40+12,D$4<'1_Assumptions'!$D$40+12+'1_Assumptions'!$D$41),1,0)*'1_Assumptions'!$D$10+IF(AND(D$4>='1_Assumptions'!$D$40+24,D$4<'1_Assumptions'!$D$40+24+'1_Assumptions'!$D$41),1,0)*'1_Assumptions'!$D$11)*'1_Assumptions'!$D$49/'1_Assumptions'!$D$41 -> 0 | E28: =(IF(AND(E$4>='1_Assumptions'!$D$40,E$4<'1_Assumptions'!$D$40+'1_Assumptions'!$D$41),1,0)*1+IF(AND(E$4>='1_Assumptions'!$D$40+12,E$4<'1_Assumptions'!$D$40+12+'1_Assumptions'!$D$41),1,0)*'1_Assumptions'!$D$10+IF(AND(E$4>='1_Assumptions'!$D$40+24,E$4<'1_Assumptions'!$D$40+24+'1_Assumptions'!$D$41),1,0)*'1_Assumptions'!$D$11)*'1_Assumptions'!$D$49/'1_Assumptions'!$D$41 -> 60000 | F28: =(IF(AND(F$4>='1_Assumptions'!$D$40,F$4<'1_Assumptions'!$D$40+'1_Assumptions'!$D$41),1,0)*1+IF(AND(F$4>='1_Assumptions'!$D$40+12,F$4<'1_Assumptions'!$D$40+12+'1_Assumptions'!$D$41),1,0)*'1_Assumptions'!$D$10+IF(AND(F$4>='1_Assumptions'!$D$40+24,F$4<'1_Assumptions'!$D$40+24+'1_Assumptions'!$D$41),1,0)*'1_Assumptions'!$D$11)*'1_Assumptions'!$D$49/'1_Assumptions'!$D$41 -> 60000 | G28: =(IF(AND(G$4>='1_Assumptions'!$D$40,G$4<'1_Assumptions'!$D$40+'1_Assumptions'!$D$41),1,0)*1+IF(AND(G$4>='1_Assumptions'!$D$40+12,G$4<'1_Assumptions'!$D$40+12+'1_Assumptions'!$D$41),1,0)*'1_Assumptions'!$D$10+IF(AND(G$4>='1_Assumptions'!$D$40+24,G$4<'1_Assumptions'!$D$40+24+'1_Assumptions'!$D$41),1,0)*'1_Assumptions'!$D$11)*'1_Assumptions'!$D$49/'1_Assumptions'!$D$41 -> 60000 | H28: =(IF(AND(H$4>='1_Assumptions'!$D$40,H$4<'1_Assumptions'!$D$40+'1_Assumptions'!$D$41),1,0)*1+IF(AND(H$4>='1_Assumptions'!$D$40+12,H$4<'1_Assumptions'!$D$40+12+'1_Assumptions'!$D$41),1,0)*'1_Assumptions'!$D$10+IF(AND(H$4>='1_Assumptions'!$D$40+24,H$4<'1_Assumptions'!$D$40+24+'1_Assumptions'!$D$41),1,0)*'1_Assumptions'!$D$11)*'1_Assumptions'!$D$49/'1_Assumptions'!$D$41 -> 60000 | I28: =(IF(AND(I$4>='1_Assumptions'!$D$40,I$4<'1_Assumptions'!$D$40+'1_Assumptions'!$D$41),1,0)*1+IF(AND(I$4>='1_Assumptions'!$D$40+12,I$4<'1_Assumptions'!$D$40+12+'1_Assumptions'!$D$41),1,0)*'1_Assumptions'!$D$10+IF(AND(I$4>='1_Assumptions'!$D$40+24,I$4<'1_Assumptions'!$D$40+24+'1_Assumptions'!$D$41),1,0)*'1_Assumptions'!$D$11)*'1_Assumptions'!$D$49/'1_Assumptions'!$D$41 -> 60000 | J28: =(IF(AND(J$4>='1_Assumptions'!$D$40,J$4<'1_Assumptions'!$D$40+'1_Assumptions'!$D$41),1,0)*1+IF(AND(J$4>='1_Assumptions'!$D$40+12,J$4<'1_Assumptions'!$D$40+12+'1_Assumptions'!$D$41),1,0)*'1_Assumptions'!$D$10+IF(AND(J$4>='1_Assumptions'!$D$40+24,J$4<'1_Assumptions'!$D$40+24+'1_Assumptions'!$D$41),1,0)*'1_Assumptions'!$D$11)*'1_Assumptions'!$D$49/'1_Assumptions'!$D$41 -> 60000 | ... AL28: =(IF(AND(AL$4>='1_Assumptions'!$D$40,AL$4<'1_Assumptions'!$D$40+'1_Assumptions'!$D$41),1,0)*1+IF(AND(AL$4>='1_Assumptions'!$D$40+12,AL$4<'1_Assumptions'!$D$40+12+'1_Assumptions'!$D$41),1,0)*'1_Assumptions'!$D$10+IF(AND(AL$4>='1_Assumptions'!$D$40+24,AL$4<'1_Assumptions'!$D$40+24+'1_Assumptions'!$D$41),1,0)*'1_Assumptions'!$D$11)*'1_Assumptions'!$D$49/'1_Assumptions'!$D$41 -> 0
B29: Processing & packaging | C29: =C10*'1_Assumptions'!$D$77 -> 0 | D29: =D10*'1_Assumptions'!$D$77 -> 0 | E29: =E10*'1_Assumptions'!$D$77 -> 0 | F29: =F10*'1_Assumptions'!$D$77 -> 0 | G29: =G10*'1_Assumptions'!$D$77 -> 0 | H29: =H10*'1_Assumptions'!$D$77 -> 0 | I29: =I10*'1_Assumptions'!$D$77 -> 0 | J29: =J10*'1_Assumptions'!$D$77 -> 0 | ... AL29: =AL10*'1_Assumptions'!$D$77 -> 71939.65
B30: Testing & compliance | C30: =(C7+C8+C9)*'1_Assumptions'!$D$54 -> 0 | D30: =(D7+D8+D9)*'1_Assumptions'!$D$54 -> 0 | E30: =(E7+E8+E9)*'1_Assumptions'!$D$54 -> 0 | F30: =(F7+F8+F9)*'1_Assumptions'!$D$54 -> 0 | G30: =(G7+G8+G9)*'1_Assumptions'!$D$54 -> 0 | H30: =(H7+H8+H9)*'1_Assumptions'!$D$54 -> 0 | I30: =(I7+I8+I9)*'1_Assumptions'!$D$54 -> 0 | J30: =(J7+J8+J9)*'1_Assumptions'!$D$54 -> 0 | ... AL30: =(AL7+AL8+AL9)*'1_Assumptions'!$D$54 -> 7500
B31: Selling & distribution (blended) | C31: =(C17+C23)*'1_Assumptions'!$D$28 -> 0 | D31: =(D17+D23)*'1_Assumptions'!$D$28 -> 0 | E31: =(E17+E23)*'1_Assumptions'!$D$28 -> 0 | F31: =(F17+F23)*'1_Assumptions'!$D$28 -> 0 | G31: =(G17+G23)*'1_Assumptions'!$D$28 -> 0 | H31: =(H17+H23)*'1_Assumptions'!$D$28 -> 0 | I31: =(I17+I23)*'1_Assumptions'!$D$28 -> 0 | J31: =(J17+J23)*'1_Assumptions'!$D$28 -> 0 | ... AL31: =(AL17+AL23)*'1_Assumptions'!$D$28 -> 390971.53
B32: Import landed cost | C32: =C22*1000*'1_Assumptions'!$D$47 -> 0 | D32: =D22*1000*'1_Assumptions'!$D$47 -> 0 | E32: =E22*1000*'1_Assumptions'!$D$47 -> 0 | F32: =F22*1000*'1_Assumptions'!$D$47 -> 0 | G32: =G22*1000*'1_Assumptions'!$D$47 -> 0 | H32: =H22*1000*'1_Assumptions'!$D$47 -> 0 | I32: =I22*1000*'1_Assumptions'!$D$47 -> 0 | J32: =J22*1000*'1_Assumptions'!$D$47 -> 0 | ... AL32: =AL22*1000*'1_Assumptions'!$D$47 -> 450000
B33: Total COGS | C33: =SUM(C28:C32) -> 0 | D33: =SUM(D28:D32) -> 0 | E33: =SUM(E28:E32) -> 60000 | F33: =SUM(F28:F32) -> 60000 | G33: =SUM(G28:G32) -> 60000 | H33: =SUM(H28:H32) -> 60000 | I33: =SUM(I28:I32) -> 60000 | J33: =SUM(J28:J32) -> 60000 | ... AL33: =SUM(AL28:AL32) -> 920411.18
B34: Gross profit | C34: =C25-C33 -> 0 | D34: =D25-D33 -> 0 | E34: =E25-E33 -> -60000 | F34: =F25-F33 -> -60000 | G34: =G25-G33 -> -60000 | H34: =H25-H33 -> -60000 | I34: =I25-I33 -> -35833 | J34: =J25-J33 -> -35833 | ... AL34: =AL25-AL33 -> 2454940.4
B36: OPERATING EXPENSES
B37: Team | C37: ='1_Assumptions'!$D$55*IF(C$4<=6,'1_Assumptions'!$D$56,1) -> 23500 | D37: ='1_Assumptions'!$D$55*IF(D$4<=6,'1_Assumptions'!$D$56,1) -> 23500 | E37: ='1_Assumptions'!$D$55*IF(E$4<=6,'1_Assumptions'!$D$56,1) -> 23500 | F37: ='1_Assumptions'!$D$55*IF(F$4<=6,'1_Assumptions'!$D$56,1) -> 23500 | G37: ='1_Assumptions'!$D$55*IF(G$4<=6,'1_Assumptions'!$D$56,1) -> 23500 | H37: ='1_Assumptions'!$D$55*IF(H$4<=6,'1_Assumptions'!$D$56,1) -> 23500 | I37: ='1_Assumptions'!$D$55*IF(I$4<=6,'1_Assumptions'!$D$56,1) -> 47000 | J37: ='1_Assumptions'!$D$55*IF(J$4<=6,'1_Assumptions'!$D$56,1) -> 47000 | ... AL37: ='1_Assumptions'!$D$55*IF(AL$4<=6,'1_Assumptions'!$D$56,1) -> 47000
B38: G&A fixed | C38: ='1_Assumptions'!$D$57 -> 26000 | D38: ='1_Assumptions'!$D$57 -> 26000 | E38: ='1_Assumptions'!$D$57 -> 26000 | F38: ='1_Assumptions'!$D$57 -> 26000 | G38: ='1_Assumptions'!$D$57 -> 26000 | H38: ='1_Assumptions'!$D$57 -> 26000 | I38: ='1_Assumptions'!$D$57 -> 26000 | J38: ='1_Assumptions'!$D$57 -> 26000 | ... AL38: ='1_Assumptions'!$D$57 -> 26000
B39: Brand & marketing | C39: =IF(C$4>='1_Assumptions'!$D$59,'1_Assumptions'!$D$58,0) -> 0 | D39: =IF(D$4>='1_Assumptions'!$D$59,'1_Assumptions'!$D$58,0) -> 0 | E39: =IF(E$4>='1_Assumptions'!$D$59,'1_Assumptions'!$D$58,0) -> 0 | F39: =IF(F$4>='1_Assumptions'!$D$59,'1_Assumptions'!$D$58,0) -> 0 | G39: =IF(G$4>='1_Assumptions'!$D$59,'1_Assumptions'!$D$58,0) -> 0 | H39: =IF(H$4>='1_Assumptions'!$D$59,'1_Assumptions'!$D$58,0) -> 0 | I39: =IF(I$4>='1_Assumptions'!$D$59,'1_Assumptions'!$D$58,0) -> 0 | J39: =IF(J$4>='1_Assumptions'!$D$59,'1_Assumptions'!$D$58,0) -> 0 | ... AL39: =IF(AL$4>='1_Assumptions'!$D$59,'1_Assumptions'!$D$58,0) -> 10000
B40: Import compliance & docs | C40: =IF(AND('0_Control'!$B$5=2,C$4>='1_Assumptions'!$D$42-2),'1_Assumptions'!$D$48,0) -> 0 | D40: =IF(AND('0_Control'!$B$5=2,D$4>='1_Assumptions'!$D$42-2),'1_Assumptions'!$D$48,0) -> 0 | E40: =IF(AND('0_Control'!$B$5=2,E$4>='1_Assumptions'!$D$42-2),'1_Assumptions'!$D$48,0) -> 0 | F40: =IF(AND('0_Control'!$B$5=2,F$4>='1_Assumptions'!$D$42-2),'1_Assumptions'!$D$48,0) -> 0 | G40: =IF(AND('0_Control'!$B$5=2,G$4>='1_Assumptions'!$D$42-2),'1_Assumptions'!$D$48,0) -> 0 | H40: =IF(AND('0_Control'!$B$5=2,H$4>='1_Assumptions'!$D$42-2),'1_Assumptions'!$D$48,0) -> 0 | I40: =IF(AND('0_Control'!$B$5=2,I$4>='1_Assumptions'!$D$42-2),'1_Assumptions'!$D$48,0) -> 0 | J40: =IF(AND('0_Control'!$B$5=2,J$4>='1_Assumptions'!$D$42-2),'1_Assumptions'!$D$48,0) -> 0 | ... AL40: =IF(AND('0_Control'!$B$5=2,AL$4>='1_Assumptions'!$D$42-2),'1_Assumptions'!$D$48,0) -> 10000
B41: Opex contingency | C41: =SUM(C37:C40)*'1_Assumptions'!$D$60 -> 4950 | D41: =SUM(D37:D40)*'1_Assumptions'!$D$60 -> 4950 | E41: =SUM(E37:E40)*'1_Assumptions'!$D$60 -> 4950 | F41: =SUM(F37:F40)*'1_Assumptions'!$D$60 -> 4950 | G41: =SUM(G37:G40)*'1_Assumptions'!$D$60 -> 4950 | H41: =SUM(H37:H40)*'1_Assumptions'!$D$60 -> 4950 | I41: =SUM(I37:I40)*'1_Assumptions'!$D$60 -> 7300 | J41: =SUM(J37:J40)*'1_Assumptions'!$D$60 -> 7300 | ... AL41: =SUM(AL37:AL40)*'1_Assumptions'!$D$60 -> 9300
B42: Total opex | C42: =SUM(C37:C41) -> 54450 | D42: =SUM(D37:D41) -> 54450 | E42: =SUM(E37:E41) -> 54450 | F42: =SUM(F37:F41) -> 54450 | G42: =SUM(G37:G41) -> 54450 | H42: =SUM(H37:H41) -> 54450 | I42: =SUM(I37:I41) -> 80300 | J42: =SUM(J37:J41) -> 80300 | ... AL42: =SUM(AL37:AL41) -> 102300
B44: EBITDA | C44: =C34-C42 -> -54450 | D44: =D34-D42 -> -54450 | E44: =E34-E42 -> -114450 | F44: =F34-F42 -> -114450 | G44: =G34-G42 -> -114450 | H44: =H34-H42 -> -114450 | I44: =I34-I42 -> -116133 | J44: =J34-J42 -> -116133 | ... AL44: =AL34-AL42 -> 2352640.4
B46: CASH FLOW
B47: Capex | C47: =IF(AND(C$4>='1_Assumptions'!$D$62,C$4<'1_Assumptions'!$D$62+'1_Assumptions'!$D$63),'1_Assumptions'!$D$61/'1_Assumptions'!$D$63,0) -> 0 | D47: =IF(AND(D$4>='1_Assumptions'!$D$62,D$4<'1_Assumptions'!$D$62+'1_Assumptions'!$D$63),'1_Assumptions'!$D$61/'1_Assumptions'!$D$63,0) -> 250000 | E47: =IF(AND(E$4>='1_Assumptions'!$D$62,E$4<'1_Assumptions'!$D$62+'1_Assumptions'!$D$63),'1_Assumptions'!$D$61/'1_Assumptions'!$D$63,0) -> 250000 | F47: =IF(AND(F$4>='1_Assumptions'!$D$62,F$4<'1_Assumptions'!$D$62+'1_Assumptions'!$D$63),'1_Assumptions'!$D$61/'1_Assumptions'!$D$63,0) -> 250000 | G47: =IF(AND(G$4>='1_Assumptions'!$D$62,G$4<'1_Assumptions'!$D$62+'1_Assumptions'!$D$63),'1_Assumptions'!$D$61/'1_Assumptions'!$D$63,0) -> 250000 | H47: =IF(AND(H$4>='1_Assumptions'!$D$62,H$4<'1_Assumptions'!$D$62+'1_Assumptions'!$D$63),'1_Assumptions'!$D$61/'1_Assumptions'!$D$63,0) -> 250000 | I47: =IF(AND(I$4>='1_Assumptions'!$D$62,I$4<'1_Assumptions'!$D$62+'1_Assumptions'!$D$63),'1_Assumptions'!$D$61/'1_Assumptions'!$D$63,0) -> 0 | J47: =IF(AND(J$4>='1_Assumptions'!$D$62,J$4<'1_Assumptions'!$D$62+'1_Assumptions'!$D$63),'1_Assumptions'!$D$61/'1_Assumptions'!$D$63,0) -> 0 | ... AL47: =IF(AND(AL$4>='1_Assumptions'!$D$62,AL$4<'1_Assumptions'!$D$62+'1_Assumptions'!$D$63),'1_Assumptions'!$D$61/'1_Assumptions'!$D$63,0) -> 0
B48: Δ Receivables (DSO) | C48: =(C25-0)*'1_Assumptions'!$D$64/30 -> 0 | D48: =(D25-C25)*'1_Assumptions'!$D$64/30 -> 0 | E48: =(E25-D25)*'1_Assumptions'!$D$64/30 -> 0 | F48: =(F25-E25)*'1_Assumptions'!$D$64/30 -> 0 | G48: =(G25-F25)*'1_Assumptions'!$D$64/30 -> 0 | H48: =(H25-G25)*'1_Assumptions'!$D$64/30 -> 0 | I48: =(I25-H25)*'1_Assumptions'!$D$64/30 -> 24167 | J48: =(J25-I25)*'1_Assumptions'!$D$64/30 -> 0 | K48: =(K25-J25)*'1_Assumptions'!$D$64/30 -> 0 | ... AL48: =(AL25-AK25)*'1_Assumptions'!$D$64/30 -> 0
B49: Δ Payables (DPO) | C49: =((C33+C42)-0)*'1_Assumptions'!$D$65/30 -> 27225 | D49: =((D33+D42)-(C33+C42))*'1_Assumptions'!$D$65/30 -> 0 | E49: =((E33+E42)-(D33+D42))*'1_Assumptions'!$D$65/30 -> 30000 | F49: =((F33+F42)-(E33+E42))*'1_Assumptions'!$D$65/30 -> 0 | G49: =((G33+G42)-(F33+F42))*'1_Assumptions'!$D$65/30 -> 0 | H49: =((H33+H42)-(G33+G42))*'1_Assumptions'!$D$65/30 -> 0 | I49: =((I33+I42)-(H33+H42))*'1_Assumptions'!$D$65/30 -> 12925 | J49: =((J33+J42)-(I33+I42))*'1_Assumptions'!$D$65/30 -> 0 | K49: =((K33+K42)-(J33+J42))*'1_Assumptions'!$D$65/30 -> 5500 | ... AL49: =((AL33+AL42)-(AK33+AK42))*'1_Assumptions'!$D$65/30 -> 0
...

Sheet 3_Annual_Summary
A1: ANNUAL & PHASE 1 SUMMARY
A2: Phase 1 = M1–M18 (matches investor deck). Years are model years (12 months each).
B4: Phase 1 (M1–M18) | C4: Year 1 (M1–M12) | D4: Year 2 (M13–M24) | E4: Year 3 (M25–M36)
A5: California revenue | B5: =SUM('2_Monthly_Model'!C19:T19) -> 12562988 | C5: =SUM('2_Monthly_Model'!C19:N19) -> 3213248.1 | D5: =SUM('2_Monthly_Model'!O19:Z19) -> 13330050 | E5: =SUM('2_Monthly_Model'!AA19:AL19) -> 16398296
A6: Import revenue | B6: =SUM('2_Monthly_Model'!C23:T23) -> 1890000 | C6: =SUM('2_Monthly_Model'!C23:N23) -> 0 | D6: =SUM('2_Monthly_Model'!O23:Z23) -> 5670000 | E6: =SUM('2_Monthly_Model'!AA23:AL23) -> 10080000
A7: Total revenue | B7: =SUM('2_Monthly_Model'!C25:T25) -> 14452988 | C7: =SUM('2_Monthly_Model'!C25:N25) -> 3213248.1 | D7: =SUM('2_Monthly_Model'!O25:Z25) -> 19000050 | E7: =SUM('2_Monthly_Model'!AA25:AL25) -> 26478296
A8: Total COGS | B8: =SUM('2_Monthly_Model'!C33:T33) -> 3686026.3 | C8: =SUM('2_Monthly_Model'!C33:N33) -> 948881.58 | D8: =SUM('2_Monthly_Model'!O33:Z33) -> 5680496.7 | E8: =SUM('2_Monthly_Model'!AA33:AL33) -> 8658878.3
A9: Gross profit | B9: =SUM('2_Monthly_Model'!C34:T34) -> 10766962 | C9: =SUM('2_Monthly_Model'!C34:N34) -> 2264366.5 | D9: =SUM('2_Monthly_Model'!O34:Z34) -> 13319553 | E9: =SUM('2_Monthly_Model'!AA34:AL34) -> 17819418
A10: Total opex | B10: =SUM('2_Monthly_Model'!C42:T42) -> 1488300 | C10: =SUM('2_Monthly_Model'!C42:N42) -> 874500 | D10: =SUM('2_Monthly_Model'!O42:Z42) -> 1227600 | E10: =SUM('2_Monthly_Model'!AA42:AL42) -> 1227600
A11: EBITDA | B11: =SUM('2_Monthly_Model'!C44:T44) -> 9278662 | C11: =SUM('2_Monthly_Model'!C44:N44) -> 1389866.5 | D11: =SUM('2_Monthly_Model'!O44:Z44) -> 12091953 | E11: =SUM('2_Monthly_Model'!AA44:AL44) -> 16591818
A12: Capex | B12: =SUM('2_Monthly_Model'!C47:T47) -> 1250000 | C12: =SUM('2_Monthly_Model'!C47:N47) -> 1250000 | D12: =SUM('2_Monthly_Model'!O47:Z47) -> 0 | E12: =SUM('2_Monthly_Model'!AA47:AL47) -> 0
A13: Tax paid | B13: =SUM('2_Monthly_Model'!C50:T50) -> 41959.95 | C13: =SUM('2_Monthly_Model'!C50:N50) -> 41959.95 | D13: =SUM('2_Monthly_Model'!O50:Z50) -> 3627585.9 | E13: =SUM('2_Monthly_Model'!AA50:AL50) -> 4977545.3
A14: Net cash flow (incl. equity) | B14: =SUM('2_Monthly_Model'!C52:T52) -> 11405157 | C14: =SUM('2_Monthly_Model'!C52:N52) -> 3707986.9 | D14: =SUM('2_Monthly_Model'!O52:Z52) -> 7650954 | E14: =SUM('2_Monthly_Model'!AA52:AL52) -> 10953609
A15: EBITDA margin | B15: =IF(B7=0,0,B11/B7) -> 0.64198917 | C15: =IF(C7=0,0,C11/C7) -> 0.43254254 | D15: =IF(D7=0,0,D11/D7) -> 0.63641692 | E15: =IF(E7=0,0,E11/E7) -> 0.62661954
A16: Closing cash (end of period) | B16: ='2_Monthly_Model'!T53 -> 11405157 | C16: ='2_Monthly_Model'!N53 -> 3707986.9 | D16: ='2_Monthly_Model'!Z53 -> 11358941 | E16: ='2_Monthly_Model'!AL53 -> 22312550
A18: Deck cross-check: Phase 1 California revenue ≈ $12.6M

Sheet 4_Use_of_Funds
A1: USE OF FUNDS — $5.0M CLEAN ASK
A2: Structure follows May 28 Clean Ask Bridge v0.3. All values USD.
A4: Item | B4: Amount | C4: % of ask | D4: Treatment / Notes
A5: California cultivation & facility build-out | B5: 1750000 | C5: =B5/$B$10 -> 0.35 | D5: Capex $1.25M (M2–M6) + Season 1 cultivation cost $0.48M. Kept.
A6: Moroccan import partnership & first inventory | B6: 1250000 | C6: =B6/$B$10 -> 0.25 | D6: Partner agreements, first inventory purchases, landed-cost float. Case B driver.
A7: Licensing, compliance & import permits | B7: 750000 | C7: =B7/$B$10 -> 0.15 | D7: CA licence costs, COA/QA programme, import regulatory pathway.
A8: Brand, sales & distribution | B8: 600000 | C8: =B8/$B$10 -> 0.12 | D8: Launch marketing, sales team ramp, distributor onboarding.
A9: Working capital & operating reserve | B9: 650000 | C9: =B9/$B$10 -> 0.13 | D9: Pre-revenue opex bridge M1–M10 + contingency. Kept separately per Clean Ask logic.
A10: TOTAL ASK | B10: =SUM(B5:B9) -> 5000000
A12: Control — ties to equity raise on 0_Control | B12: =B10-'0_Control'!B9 -> 0
A13: Model minimum cash balance (M1–M36) — must stay positive | B13: =MIN('2_Monthly_Model'!C53:AL53) -> 2528397.6

Sheet 5_Scenarios_Stress
A1: SCENARIOS & STRESS TESTS
A2: Case A = California only. Case B = California + Moroccan imports. Proxy sensitivities follow v0.7 5A logic; full rerun by editing 1_Assumptions.
A4: Metric | B4: Case A (CA only) | C4: Case B (+ imports) | D4: Notes
A5: Phase 1 revenue (M1–M18) | B5: =SUM('2_Monthly_Model'!C19:T19) -> 12562988 | C5: =SUM('2_Monthly_Model'!C19:T19)+SUM('2_Monthly_Model'!C23:T23) -> 14452988 | D5: Import column is zero when toggle = 1
A6: Year 2 total revenue | B6: =SUM('2_Monthly_Model'!O19:Z19) -> 13330050 | C6: =SUM('2_Monthly_Model'!O25:Z25) -> 19000050
A7: Year 3 total revenue | B7: =SUM('2_Monthly_Model'!AA19:AL19) -> 16398296 | C7: =SUM('2_Monthly_Model'!AA25:AL25) -> 26478296
A8: Phase 1 import gross profit | B8: =0 -> 0 | C8: =SUM('2_Monthly_Model'!C23:T23)-SUM('2_Monthly_Model'!C32:T32) -> 1080000 | D8: Pre-distribution
A10: Set 0_Control toggle = 2 for Case B figures to flow through monthly model; Case A column here strips import rows directly.
A12: Stress lever | B12: Base input | C12: Stress input | D12: Metric | E12: Base output | F12: Stress proxy output | G12: Delta
A13: All-wholesale mix (B2C share 0%) | B13: 50% | C13: 0% | D13: Season product revenue | E13: ='1_Assumptions'!$D$78 -> 12272984 | F13: ='1_Assumptions'!$D$78*'1_Assumptions'!$D$24/'1_Assumptions'!$D$27 -> 8181989.5 | G13: =F13-E13 -> -4090994.8
A14: All-retail mix (B2C share 100%) | B14: 50% | C14: 100% | D14: Season product revenue | E14: ='1_Assumptions'!$D$78 -> 12272984 | F14: ='1_Assumptions'!$D$78/'1_Assumptions'!$D$27 -> 16363979 | G14: =F14-E14 -> 4090994.8
A15: Season 1 yield −20% | B15: 2094 | C15: 1675 | D15: Season product revenue | E15: ='1_Assumptions'!$D$78 -> 12272984 | F15: ='1_Assumptions'!$D$78*0.8 -> 9818387.4 | G15: =F15-E15 -> -2454596.9
A16: Wholesale price 40% of retail (vs 50%) | B16: 50% | C16: 40% | D16: Season product revenue | E16: ='1_Assumptions'!$D$78 -> 12272984 | F16: ='1_Assumptions'!$D$78*('1_Assumptions'!$D$23+(1-'1_Assumptions'!$D$23)*0.4)/'1_Assumptions'!$D$27 -> 11454785 | G16: =F16-E16 -> -818198.95
A17: Import price −30% | B17: 10.5 | C17: 7.35 | D17: Y2 import revenue | E17: ='1_Assumptions'!$D$44*12*1000*'1_Assumptions'!$D$46 -> 7560000 | F17: ='1_Assumptions'!$D$44*12*1000*7.35 -> 5292000 | G17: =F17-E17 -> -2268000

Sheet 6_Valuation
A1: VALUATION VIEW
A2: DCF on 36-month FCF plus Year 3 EBITDA reference multiple. Methodology carried over from v0.7 8_Valuation.
A4: Metric | B4: Value | C4: Notes
A5: Year 3 EBITDA | B5: ='3_Annual_Summary'!E11 -> 16591818 | C5: Model year 3
A6: EV @ 6x Y3 EBITDA | B6: =B5*'1_Assumptions'!$D$68 -> 99550906 | C6: Reference multiple from v0.7
A7: EV @ 8x Y3 EBITDA | B7: =B5*8 -> 1.3273454e+08
A8: NPV of 36-month FCF @ 22% | B8: =('2_Monthly_Model'!C44-'2_Monthly_Model'!C47-'2_Monthly_Model'!C50)/(1+((1+'1_Assumptions'!$D$67)^(1/12)-1))^1+('2_Monthly_Model'!D44-'2_Monthly_Model'!D47-'2_Monthly_Model'!D50)/(1+((1+'1_Assumptions'!$D$67)^(1/12)-1))^2+('2_Monthly_Model'!E44-'2_Monthly_Model'!E47-'2_Monthly_Model'!E50)/(1+((1+'1_Assumptions'!$D$67)^(1/12)-1))^3+('2_Monthly_Model'!F44-'2_Monthly_Model'!F47-'2_Monthly_Model'!F50)/(1+((1+'1_Assumptions'!$D$67)^(1/12)-1))^4+('2_Monthly_Model'!G44-'2_Monthly_Model'!G47-'2_Monthly_Model'!G50)/(1+((1+'1_Assumptions'!$D$67)^(1/12)-1))^5+('2_Monthly_Model'!H44-'2_Monthly_Model'!H47-'2_Monthly_Model'!H50)/(1+((1+'1_Assumptions'!$D$67)^(1/12)-1))^6+('2_Monthly_Model'!I44-'2_Monthly_Model'!I47-'2_Monthly_Model'!I50)/(1+((1+'1_Assumptions'!$D$67)^(1/12)-1))^7+('2_Monthly_Model'!J44-'2_Monthly_Model'!J47-'2_Monthly_Model'!J50)/(1+((1+'1_Assumptions'!$D$67)^(1/12)-1))^8+('2_Monthly_Model'!K44-'2_Monthly_Model'!K47-'2_Monthly_Model'!K50)/(1+((1+'1_Assumptions'!$D$67)^(1/12)-1))^9+('2_Monthly_Model'!L44-'2_Monthly_Model'!L47-'2_Monthly_Model'!L50)/(1+((1+'1_Assumptions'!$D$67)^(1/12)-1))^10+('2_Monthly_Model'!M44-'2_Monthly_Model'!M47-'2_Monthly_Model'!M50)/(1+((1+'1_Assumptions'!$D$67)^(1/12)-1))^11+('2_Monthly_Model'!N44-'2_Monthly_Model'!N47-'2_Monthly_Model'!N50)/(1+((1+'1_Assumptions'!$D$67)^(1/12)-1))^12+('2_Monthly_Model'!O44-'2_Monthly_Model'!O47-'2_Monthly_Model'!O50)/(1+((1+'1_Assumptions'!$D$67)^(1/12)-1))^13+('2_Monthly_Model'!P44-'2_Monthly_Model'!P47-'2_Monthly_Model'!P50)/(1+((1+'1_Assumptions'!$D$67)^(1/12)-1))^14+('2_Monthly_Model'!Q44-'2_Monthly_Model'!Q47-'2_Monthly_Model'!Q50)/(1+((1+'1_Assumptions'!$D$67)^(1/12)-1))^15+('2_Monthly_Model'!R44-'2_Monthly_Model'!R47-'2_Monthly_Model'!R50)/(1+((1+'1_Assumptions'!$D$67)^(1/12)-1))^16+('2_Monthly_Model'!S44-'2_Monthly_Model'!S47-'2_Monthly_Model'!S50)/(1+((1+'1_Assumptions'!$D$67)^(1/12)-1))^17+('2_Monthly_Model'!T44-'2_Monthly_Model'!T47-'2_Monthly_Model'!T50)/(1+((1+'1_Assumptions'!$D$67)^(1/12)-1))^18+('2_Monthly_Model'!U44-'2_Monthly_Model'!U47-'2_Monthly_Model'!U50)/(1+((1+'1_Assumptions'!$D$67)^(1/12)-1))^19+('2_Monthly_Model'!V44-'2_Monthly_Model'!V47-'2_Monthly_Model'!V50)/(1+((1+'1_Assumptions'!$D$67)^(1/12)-1))^20+('2_Monthly_Model'!W44-'2_Monthly_Model'!W47-'2_Monthly_Model'!W50)/(1+((1+'1_Assumptions'!$D$67)^(1/12)-1))^21+('2_Monthly_Model'!X44-'2_Monthly_Model'!X47-'2_Monthly_Model'!X50)/(1+((1+'1_Assumptions'!$D$67)^(1/12)-1))^22+('2_Monthly_Model'!Y44-'2_Monthly_Model'!Y47-'2_Monthly_Model'!Y50)/(1+((1+'1_Assumptions'!$D$67)^(1/12)-1))^23+('2_Monthly_Model'!Z44-'2_Monthly_Model'!Z47-'2_Monthly_Model'!Z50)/(1+((1+'1_Assumptions'!$D$67)^(1/12)-1))^24+('2_Monthly_Model'!AA44-'2_Monthly_Model'!AA47-'2_Monthly_Model'!AA50)/(1+((1+'1_Assumptions'!$D$67)^(1/12)-1))^25+('2_Monthly_Model'!AB44-'2_Monthly_Model'!AB47-'2_Monthly_Model'!AB50)/(1+((1+'1_Assumptions'!$D$67)^(1/12)-1))^26+('2_Monthly_Model'!AC44-'2_Monthly_Model'!AC47-'2_Monthly_Model'!AC50)/(1+((1+'1_Assumptions'!$D$67)^(1/12)-1))^27+('2_Monthly_Model'!AD44-'2_Monthly_Model'!AD47-'2_Monthly_Model'!AD50)/(1+((1+'1_Assumptions'!$D$67)^(1/12)-1))^28+('2_Monthly_Model'!AE44-'2_Monthly_Model'!AE47-'2_Monthly_Model'!AE50)/(1+((1+'1_Assumptions'!$D$67)^(1/12)-1))^29+('2_Monthly_Model'!AF44-'2_Monthly_Model'!AF47-'2_Monthly_Model'!AF50)/(1+((1+'1_Assumptions'!$D$67)^(1/12)-1))^30+('2_Monthly_Model'!AG44-'2_Monthly_Model'!AG47-'2_Monthly_Model'!AG50)/(1+((1+'1_Assumptions'!$D$67)^(1/12)-1))^31+('2_Monthly_Model'!AH44-'2_Monthly_Model'!AH47-'2_Monthly_Model'!AH50)/(1+((1+'1_Assumptions'!$D$67)^(1/12)-1))^32+('2_Monthly_Model'!AI44-'2_Monthly_Model'!AI47-'2_Monthly_Model'!AI50)/(1+((1+'1_Assumptions'!$D$67)^(1/12)-1))^33+('2_Monthly_Model'!AJ44-'2_Monthly_Model'!AJ47-'2_Monthly_Model'!AJ50)/(1+((1+'1_Assumptions'!$D$67)^(1/12)-1))^34+('2_Monthly_Model'!AK44-'2_Monthly_Model'!AK47-'2_Monthly_Model'!AK50)/(1+((1+'1_Assumptions'!$D$67)^(1/12)-1))^35+('2_Monthly_Model'!AL44-'2_Monthly_Model'!AL47-'2_Monthly_Model'!AL50)/(1+((1+'1_Assumptions'!$D$67)^(1/12)-1))^36 -> 13750168 | C8: Pre-equity, post-tax operating FCF
A9: Terminal value (Y3 EBITDA × 6, discounted) | B9: =B6/(1+'1_Assumptions'!$D$67)^3 -> 54823369
A10: Indicative enterprise value (NPV + TV) | B10: =B8+B9 -> 68573537 | C10: Illustrative — not a guarantee
A11: Multiple on $5.0M raise (EV basis) | B11: =B10/'0_Control'!B9 -> 13.714707 | C11: Read-through only; ignores dilution/structure
